from anaconda_auth.exceptions import *  # noqa: F403
from anaconda_cloud_auth import warn  # noqa: F401

warn()
